2025-01-12 10:55:29.420 WARNING (SyncWorker_1) [homeassistant.loader] We found a custom integration pirateweather which has not been tested by Home Assistant. This component might cause stability problems, be sure to disable it if you experience issues with Home Assistant
2025-01-12 10:55:29.421 WARNING (SyncWorker_1) [homeassistant.loader] We found a custom integration birdbuddy which has not been tested by Home Assistant. This component might cause stability problems, be sure to disable it if you experience issues with Home Assistant
2025-01-12 10:55:29.422 WARNING (SyncWorker_1) [homeassistant.loader] We found a custom integration hacs which has not been tested by Home Assistant. This component might cause stability problems, be sure to disable it if you experience issues with Home Assistant
2025-01-12 10:55:29.423 WARNING (SyncWorker_1) [homeassistant.loader] We found a custom integration nintendo_parental which has not been tested by Home Assistant. This component might cause stability problems, be sure to disable it if you experience issues with Home Assistant
2025-01-12 10:55:29.424 WARNING (SyncWorker_1) [homeassistant.loader] We found a custom integration samsungtv_smart which has not been tested by Home Assistant. This component might cause stability problems, be sure to disable it if you experience issues with Home Assistant
2025-01-12 10:55:29.425 WARNING (SyncWorker_1) [homeassistant.loader] We found a custom integration browser_mod which has not been tested by Home Assistant. This component might cause stability problems, be sure to disable it if you experience issues with Home Assistant
2025-01-12 10:55:29.426 WARNING (SyncWorker_1) [homeassistant.loader] We found a custom integration webrtc which has not been tested by Home Assistant. This component might cause stability problems, be sure to disable it if you experience issues with Home Assistant
2025-01-12 10:55:29.427 WARNING (SyncWorker_1) [homeassistant.loader] We found a custom integration icloud3 which has not been tested by Home Assistant. This component might cause stability problems, be sure to disable it if you experience issues with Home Assistant
2025-01-12 10:55:29.429 WARNING (SyncWorker_1) [homeassistant.loader] We found a custom integration asusrouter which has not been tested by Home Assistant. This component might cause stability problems, be sure to disable it if you experience issues with Home Assistant
2025-01-12 11:05:44.087 ERROR (MainThread) [homeassistant.components.automation.collect_bird_buddy_postcard] Collect Bird Buddy Postcard: Error executing script. Invalid data for call_service at pos 1: value should be a string for dictionary value @ data['device_id']
2025-01-12 11:05:44.087 ERROR (MainThread) [homeassistant.components.automation.collect_bird_buddy_postcard] Error while executing automation automation.collect_bird_buddy_postcard: value should be a string for dictionary value @ data['device_id']
2025-01-12 11:05:44.483 ERROR (MainThread) [homeassistant.components.automation.collect_bird_buddy_postcard] Collect Bird Buddy Postcard: Error executing script. Invalid data for call_service at pos 1: value should be a string for dictionary value @ data['device_id']
2025-01-12 11:05:44.484 ERROR (MainThread) [homeassistant.components.automation.collect_bird_buddy_postcard] Error while executing automation automation.collect_bird_buddy_postcard: value should be a string for dictionary value @ data['device_id']
2025-01-12 11:05:44.754 ERROR (MainThread) [homeassistant.components.automation.collect_bird_buddy_postcard] Collect Bird Buddy Postcard: Error executing script. Invalid data for call_service at pos 1: value should be a string for dictionary value @ data['device_id']
2025-01-12 11:05:44.754 ERROR (MainThread) [homeassistant.components.automation.collect_bird_buddy_postcard] Error while executing automation automation.collect_bird_buddy_postcard: value should be a string for dictionary value @ data['device_id']
2025-01-12 11:05:45.039 ERROR (MainThread) [homeassistant.components.automation.collect_bird_buddy_postcard] Collect Bird Buddy Postcard: Error executing script. Invalid data for call_service at pos 1: value should be a string for dictionary value @ data['device_id']
2025-01-12 11:05:45.039 ERROR (MainThread) [homeassistant.components.automation.collect_bird_buddy_postcard] Error while executing automation automation.collect_bird_buddy_postcard: value should be a string for dictionary value @ data['device_id']
2025-01-12 11:05:46.549 ERROR (MainThread) [homeassistant.components.automation.collect_bird_buddy_postcard] Collect Bird Buddy Postcard: Error executing script. Invalid data for call_service at pos 1: value should be a string for dictionary value @ data['device_id']
2025-01-12 11:05:46.549 ERROR (MainThread) [homeassistant.components.automation.collect_bird_buddy_postcard] Error while executing automation automation.collect_bird_buddy_postcard: value should be a string for dictionary value @ data['device_id']
2025-01-12 11:05:47.153 ERROR (MainThread) [homeassistant.components.automation.collect_bird_buddy_postcard] Collect Bird Buddy Postcard: Error executing script. Invalid data for call_service at pos 1: value should be a string for dictionary value @ data['device_id']
2025-01-12 11:05:47.153 ERROR (MainThread) [homeassistant.components.automation.collect_bird_buddy_postcard] Error while executing automation automation.collect_bird_buddy_postcard: value should be a string for dictionary value @ data['device_id']
2025-01-12 11:05:47.415 ERROR (MainThread) [homeassistant.components.automation.collect_bird_buddy_postcard] Collect Bird Buddy Postcard: Error executing script. Invalid data for call_service at pos 1: value should be a string for dictionary value @ data['device_id']
2025-01-12 11:05:47.417 ERROR (MainThread) [homeassistant.components.automation.collect_bird_buddy_postcard] Error while executing automation automation.collect_bird_buddy_postcard: value should be a string for dictionary value @ data['device_id']
2025-01-12 11:05:47.794 ERROR (MainThread) [homeassistant.components.automation.collect_bird_buddy_postcard] Collect Bird Buddy Postcard: Error executing script. Invalid data for call_service at pos 1: value should be a string for dictionary value @ data['device_id']
2025-01-12 11:05:47.794 ERROR (MainThread) [homeassistant.components.automation.collect_bird_buddy_postcard] Error while executing automation automation.collect_bird_buddy_postcard: value should be a string for dictionary value @ data['device_id']
2025-01-12 11:05:48.085 ERROR (MainThread) [homeassistant.components.automation.collect_bird_buddy_postcard] Collect Bird Buddy Postcard: Error executing script. Invalid data for call_service at pos 1: value should be a string for dictionary value @ data['device_id']
2025-01-12 11:05:48.086 ERROR (MainThread) [homeassistant.components.automation.collect_bird_buddy_postcard] Error while executing automation automation.collect_bird_buddy_postcard: value should be a string for dictionary value @ data['device_id']
2025-01-12 11:05:48.523 ERROR (MainThread) [homeassistant.components.automation.collect_bird_buddy_postcard] Collect Bird Buddy Postcard: Error executing script. Invalid data for call_service at pos 1: value should be a string for dictionary value @ data['device_id']
2025-01-12 11:05:48.523 ERROR (MainThread) [homeassistant.components.automation.collect_bird_buddy_postcard] Error while executing automation automation.collect_bird_buddy_postcard: value should be a string for dictionary value @ data['device_id']
2025-01-12 11:05:48.957 ERROR (MainThread) [homeassistant.components.automation.collect_bird_buddy_postcard] Collect Bird Buddy Postcard: Error executing script. Invalid data for call_service at pos 1: value should be a string for dictionary value @ data['device_id']
2025-01-12 11:05:48.957 ERROR (MainThread) [homeassistant.components.automation.collect_bird_buddy_postcard] Error while executing automation automation.collect_bird_buddy_postcard: value should be a string for dictionary value @ data['device_id']
2025-01-12 11:05:49.312 ERROR (MainThread) [homeassistant.components.automation.collect_bird_buddy_postcard] Collect Bird Buddy Postcard: Error executing script. Invalid data for call_service at pos 1: value should be a string for dictionary value @ data['device_id']
2025-01-12 11:05:49.312 ERROR (MainThread) [homeassistant.components.automation.collect_bird_buddy_postcard] Error while executing automation automation.collect_bird_buddy_postcard: value should be a string for dictionary value @ data['device_id']
2025-01-12 11:05:49.700 ERROR (MainThread) [homeassistant.components.automation.collect_bird_buddy_postcard] Collect Bird Buddy Postcard: Error executing script. Invalid data for call_service at pos 1: value should be a string for dictionary value @ data['device_id']
2025-01-12 11:05:49.700 ERROR (MainThread) [homeassistant.components.automation.collect_bird_buddy_postcard] Error while executing automation automation.collect_bird_buddy_postcard: value should be a string for dictionary value @ data['device_id']
2025-01-12 11:05:50.034 ERROR (MainThread) [homeassistant.components.automation.collect_bird_buddy_postcard] Collect Bird Buddy Postcard: Error executing script. Invalid data for call_service at pos 1: value should be a string for dictionary value @ data['device_id']
2025-01-12 11:05:50.034 ERROR (MainThread) [homeassistant.components.automation.collect_bird_buddy_postcard] Error while executing automation automation.collect_bird_buddy_postcard: value should be a string for dictionary value @ data['device_id']
2025-01-12 11:05:50.483 ERROR (MainThread) [homeassistant.components.automation.collect_bird_buddy_postcard] Collect Bird Buddy Postcard: Error executing script. Invalid data for call_service at pos 1: value should be a string for dictionary value @ data['device_id']
2025-01-12 11:05:50.483 ERROR (MainThread) [homeassistant.components.automation.collect_bird_buddy_postcard] Error while executing automation automation.collect_bird_buddy_postcard: value should be a string for dictionary value @ data['device_id']
2025-01-12 11:05:50.753 ERROR (MainThread) [homeassistant.components.automation.collect_bird_buddy_postcard] Collect Bird Buddy Postcard: Error executing script. Invalid data for call_service at pos 1: value should be a string for dictionary value @ data['device_id']
2025-01-12 11:05:50.753 ERROR (MainThread) [homeassistant.components.automation.collect_bird_buddy_postcard] Error while executing automation automation.collect_bird_buddy_postcard: value should be a string for dictionary value @ data['device_id']
2025-01-12 11:05:51.152 ERROR (MainThread) [homeassistant.components.automation.collect_bird_buddy_postcard] Collect Bird Buddy Postcard: Error executing script. Invalid data for call_service at pos 1: value should be a string for dictionary value @ data['device_id']
2025-01-12 11:05:51.152 ERROR (MainThread) [homeassistant.components.automation.collect_bird_buddy_postcard] Error while executing automation automation.collect_bird_buddy_postcard: value should be a string for dictionary value @ data['device_id']
2025-01-12 11:05:51.595 ERROR (MainThread) [homeassistant.components.automation.collect_bird_buddy_postcard] Collect Bird Buddy Postcard: Error executing script. Invalid data for call_service at pos 1: value should be a string for dictionary value @ data['device_id']
2025-01-12 11:05:51.595 ERROR (MainThread) [homeassistant.components.automation.collect_bird_buddy_postcard] Error while executing automation automation.collect_bird_buddy_postcard: value should be a string for dictionary value @ data['device_id']
2025-01-12 11:05:52.081 ERROR (MainThread) [homeassistant.components.automation.collect_bird_buddy_postcard] Collect Bird Buddy Postcard: Error executing script. Invalid data for call_service at pos 1: value should be a string for dictionary value @ data['device_id']
2025-01-12 11:05:52.081 ERROR (MainThread) [homeassistant.components.automation.collect_bird_buddy_postcard] Error while executing automation automation.collect_bird_buddy_postcard: value should be a string for dictionary value @ data['device_id']
2025-01-12 11:05:52.459 ERROR (MainThread) [homeassistant.components.automation.collect_bird_buddy_postcard] Collect Bird Buddy Postcard: Error executing script. Invalid data for call_service at pos 1: value should be a string for dictionary value @ data['device_id']
2025-01-12 11:05:52.460 ERROR (MainThread) [homeassistant.components.automation.collect_bird_buddy_postcard] Error while executing automation automation.collect_bird_buddy_postcard: value should be a string for dictionary value @ data['device_id']
2025-01-12 11:13:04.746 ERROR (MainThread) [homeassistant.components.websocket_api.http.connection] [140124422684336] Supervisor from 172.30.32.2 (HomeAssistantSupervisor/2024.12.3 aiohttp/3.11.11 Python/3.12): Unexpected error inside websocket API
Traceback (most recent call last):
  File "/usr/src/homeassistant/homeassistant/components/websocket_api/http.py", line 343, in async_handle
    await self._async_websocket_command_phase(connection)
  File "/usr/src/homeassistant/homeassistant/components/websocket_api/http.py", line 463, in _async_websocket_command_phase
    msg = await wsock.receive()
          ^^^^^^^^^^^^^^^^^^^^^
  File "/usr/local/lib/python3.13/site-packages/aiohttp/web_ws.py", line 575, in receive
    await self.pong(msg.data)
  File "/usr/local/lib/python3.13/site-packages/aiohttp/web_ws.py", line 393, in pong
    await self._writer.send_frame(message, WSMsgType.PONG)
  File "/usr/local/lib/python3.13/site-packages/aiohttp/_websocket/writer.py", line 125, in send_frame
    raise ClientConnectionResetError("Cannot write to closing transport")
aiohttp.client_exceptions.ClientConnectionResetError: Cannot write to closing transport
2025-01-12 11:13:05.631 ERROR (MainThread) [homeassistant.components.websocket_api.http.connection] [140124417428208] Supervisor from 172.30.32.2 (HomeAssistantSupervisor/2024.12.3 aiohttp/3.11.11 Python/3.12): Unexpected error inside websocket API
Traceback (most recent call last):
  File "/usr/src/homeassistant/homeassistant/components/websocket_api/http.py", line 343, in async_handle
    await self._async_websocket_command_phase(connection)
  File "/usr/src/homeassistant/homeassistant/components/websocket_api/http.py", line 463, in _async_websocket_command_phase
    msg = await wsock.receive()
          ^^^^^^^^^^^^^^^^^^^^^
  File "/usr/local/lib/python3.13/site-packages/aiohttp/web_ws.py", line 575, in receive
    await self.pong(msg.data)
  File "/usr/local/lib/python3.13/site-packages/aiohttp/web_ws.py", line 393, in pong
    await self._writer.send_frame(message, WSMsgType.PONG)
  File "/usr/local/lib/python3.13/site-packages/aiohttp/_websocket/writer.py", line 125, in send_frame
    raise ClientConnectionResetError("Cannot write to closing transport")
aiohttp.client_exceptions.ClientConnectionResetError: Cannot write to closing transport
2025-01-12 11:13:05.642 ERROR (MainThread) [homeassistant.components.websocket_api.http.connection] [140124422678288] Supervisor from 172.30.32.2 (HomeAssistantSupervisor/2024.12.3 aiohttp/3.11.11 Python/3.12): Unexpected error inside websocket API
Traceback (most recent call last):
  File "/usr/src/homeassistant/homeassistant/components/websocket_api/http.py", line 343, in async_handle
    await self._async_websocket_command_phase(connection)
  File "/usr/src/homeassistant/homeassistant/components/websocket_api/http.py", line 463, in _async_websocket_command_phase
    msg = await wsock.receive()
          ^^^^^^^^^^^^^^^^^^^^^
  File "/usr/local/lib/python3.13/site-packages/aiohttp/web_ws.py", line 575, in receive
    await self.pong(msg.data)
  File "/usr/local/lib/python3.13/site-packages/aiohttp/web_ws.py", line 393, in pong
    await self._writer.send_frame(message, WSMsgType.PONG)
  File "/usr/local/lib/python3.13/site-packages/aiohttp/_websocket/writer.py", line 125, in send_frame
    raise ClientConnectionResetError("Cannot write to closing transport")
aiohttp.client_exceptions.ClientConnectionResetError: Cannot write to closing transport
2025-01-12 11:13:05.643 ERROR (MainThread) [homeassistant.components.websocket_api.http.connection] [140124417431664] Supervisor from 172.30.32.2 (HomeAssistantSupervisor/2024.12.3 aiohttp/3.11.11 Python/3.12): Unexpected error inside websocket API
Traceback (most recent call last):
  File "/usr/src/homeassistant/homeassistant/components/websocket_api/http.py", line 343, in async_handle
    await self._async_websocket_command_phase(connection)
  File "/usr/src/homeassistant/homeassistant/components/websocket_api/http.py", line 463, in _async_websocket_command_phase
    msg = await wsock.receive()
          ^^^^^^^^^^^^^^^^^^^^^
  File "/usr/local/lib/python3.13/site-packages/aiohttp/web_ws.py", line 575, in receive
    await self.pong(msg.data)
  File "/usr/local/lib/python3.13/site-packages/aiohttp/web_ws.py", line 393, in pong
    await self._writer.send_frame(message, WSMsgType.PONG)
  File "/usr/local/lib/python3.13/site-packages/aiohttp/_websocket/writer.py", line 125, in send_frame
    raise ClientConnectionResetError("Cannot write to closing transport")
aiohttp.client_exceptions.ClientConnectionResetError: Cannot write to closing transport
2025-01-12 11:13:05.644 ERROR (MainThread) [homeassistant.components.websocket_api.http.connection] [140124438688624] Supervisor from 172.30.32.2 (HomeAssistantSupervisor/2024.12.3 aiohttp/3.11.11 Python/3.12): Unexpected error inside websocket API
Traceback (most recent call last):
  File "/usr/src/homeassistant/homeassistant/components/websocket_api/http.py", line 343, in async_handle
    await self._async_websocket_command_phase(connection)
  File "/usr/src/homeassistant/homeassistant/components/websocket_api/http.py", line 463, in _async_websocket_command_phase
    msg = await wsock.receive()
          ^^^^^^^^^^^^^^^^^^^^^
  File "/usr/local/lib/python3.13/site-packages/aiohttp/web_ws.py", line 575, in receive
    await self.pong(msg.data)
  File "/usr/local/lib/python3.13/site-packages/aiohttp/web_ws.py", line 393, in pong
    await self._writer.send_frame(message, WSMsgType.PONG)
  File "/usr/local/lib/python3.13/site-packages/aiohttp/_websocket/writer.py", line 125, in send_frame
    raise ClientConnectionResetError("Cannot write to closing transport")
aiohttp.client_exceptions.ClientConnectionResetError: Cannot write to closing transport
2025-01-12 11:13:05.645 ERROR (MainThread) [homeassistant.components.websocket_api.http.connection] [140124422678864] Supervisor from 172.30.32.2 (HomeAssistantSupervisor/2024.12.3 aiohttp/3.11.11 Python/3.12): Unexpected error inside websocket API
Traceback (most recent call last):
  File "/usr/src/homeassistant/homeassistant/components/websocket_api/http.py", line 343, in async_handle
    await self._async_websocket_command_phase(connection)
  File "/usr/src/homeassistant/homeassistant/components/websocket_api/http.py", line 463, in _async_websocket_command_phase
    msg = await wsock.receive()
          ^^^^^^^^^^^^^^^^^^^^^
  File "/usr/local/lib/python3.13/site-packages/aiohttp/web_ws.py", line 575, in receive
    await self.pong(msg.data)
  File "/usr/local/lib/python3.13/site-packages/aiohttp/web_ws.py", line 393, in pong
    await self._writer.send_frame(message, WSMsgType.PONG)
  File "/usr/local/lib/python3.13/site-packages/aiohttp/_websocket/writer.py", line 125, in send_frame
    raise ClientConnectionResetError("Cannot write to closing transport")
aiohttp.client_exceptions.ClientConnectionResetError: Cannot write to closing transport
2025-01-12 11:13:05.646 ERROR (MainThread) [homeassistant.components.websocket_api.http.connection] [140124420629712] Supervisor from 172.30.32.2 (HomeAssistantSupervisor/2024.12.3 aiohttp/3.11.11 Python/3.12): Unexpected error inside websocket API
Traceback (most recent call last):
  File "/usr/src/homeassistant/homeassistant/components/websocket_api/http.py", line 343, in async_handle
    await self._async_websocket_command_phase(connection)
  File "/usr/src/homeassistant/homeassistant/components/websocket_api/http.py", line 463, in _async_websocket_command_phase
    msg = await wsock.receive()
          ^^^^^^^^^^^^^^^^^^^^^
  File "/usr/local/lib/python3.13/site-packages/aiohttp/web_ws.py", line 575, in receive
    await self.pong(msg.data)
  File "/usr/local/lib/python3.13/site-packages/aiohttp/web_ws.py", line 393, in pong
    await self._writer.send_frame(message, WSMsgType.PONG)
  File "/usr/local/lib/python3.13/site-packages/aiohttp/_websocket/writer.py", line 125, in send_frame
    raise ClientConnectionResetError("Cannot write to closing transport")
aiohttp.client_exceptions.ClientConnectionResetError: Cannot write to closing transport
2025-01-12 11:13:05.647 ERROR (MainThread) [homeassistant.components.websocket_api.http.connection] [140124422678432] Supervisor from 172.30.32.2 (HomeAssistantSupervisor/2024.12.3 aiohttp/3.11.11 Python/3.12): Unexpected error inside websocket API
Traceback (most recent call last):
  File "/usr/src/homeassistant/homeassistant/components/websocket_api/http.py", line 343, in async_handle
    await self._async_websocket_command_phase(connection)
  File "/usr/src/homeassistant/homeassistant/components/websocket_api/http.py", line 463, in _async_websocket_command_phase
    msg = await wsock.receive()
          ^^^^^^^^^^^^^^^^^^^^^
  File "/usr/local/lib/python3.13/site-packages/aiohttp/web_ws.py", line 575, in receive
    await self.pong(msg.data)
  File "/usr/local/lib/python3.13/site-packages/aiohttp/web_ws.py", line 393, in pong
    await self._writer.send_frame(message, WSMsgType.PONG)
  File "/usr/local/lib/python3.13/site-packages/aiohttp/_websocket/writer.py", line 125, in send_frame
    raise ClientConnectionResetError("Cannot write to closing transport")
aiohttp.client_exceptions.ClientConnectionResetError: Cannot write to closing transport
2025-01-12 11:13:05.647 ERROR (MainThread) [homeassistant.components.websocket_api.http.connection] [140124443992720] Supervisor from 172.30.32.2 (HomeAssistantSupervisor/2024.12.3 aiohttp/3.11.11 Python/3.12): Unexpected error inside websocket API
Traceback (most recent call last):
  File "/usr/src/homeassistant/homeassistant/components/websocket_api/http.py", line 343, in async_handle
    await self._async_websocket_command_phase(connection)
  File "/usr/src/homeassistant/homeassistant/components/websocket_api/http.py", line 463, in _async_websocket_command_phase
    msg = await wsock.receive()
          ^^^^^^^^^^^^^^^^^^^^^
  File "/usr/local/lib/python3.13/site-packages/aiohttp/web_ws.py", line 575, in receive
    await self.pong(msg.data)
  File "/usr/local/lib/python3.13/site-packages/aiohttp/web_ws.py", line 393, in pong
    await self._writer.send_frame(message, WSMsgType.PONG)
  File "/usr/local/lib/python3.13/site-packages/aiohttp/_websocket/writer.py", line 125, in send_frame
    raise ClientConnectionResetError("Cannot write to closing transport")
aiohttp.client_exceptions.ClientConnectionResetError: Cannot write to closing transport
2025-01-12 11:13:05.648 ERROR (MainThread) [homeassistant.components.websocket_api.http.connection] [140124418652864] Supervisor from 172.30.32.2 (HomeAssistantSupervisor/2024.12.3 aiohttp/3.11.11 Python/3.12): Unexpected error inside websocket API
Traceback (most recent call last):
  File "/usr/src/homeassistant/homeassistant/components/websocket_api/http.py", line 343, in async_handle
    await self._async_websocket_command_phase(connection)
  File "/usr/src/homeassistant/homeassistant/components/websocket_api/http.py", line 463, in _async_websocket_command_phase
    msg = await wsock.receive()
          ^^^^^^^^^^^^^^^^^^^^^
  File "/usr/local/lib/python3.13/site-packages/aiohttp/web_ws.py", line 575, in receive
    await self.pong(msg.data)
  File "/usr/local/lib/python3.13/site-packages/aiohttp/web_ws.py", line 393, in pong
    await self._writer.send_frame(message, WSMsgType.PONG)
  File "/usr/local/lib/python3.13/site-packages/aiohttp/_websocket/writer.py", line 125, in send_frame
    raise ClientConnectionResetError("Cannot write to closing transport")
aiohttp.client_exceptions.ClientConnectionResetError: Cannot write to closing transport
2025-01-12 11:13:05.649 ERROR (MainThread) [homeassistant.components.websocket_api.http.connection] [140124421493168] Supervisor from 172.30.32.2 (HomeAssistantSupervisor/2024.12.3 aiohttp/3.11.11 Python/3.12): Unexpected error inside websocket API
Traceback (most recent call last):
  File "/usr/src/homeassistant/homeassistant/components/websocket_api/http.py", line 343, in async_handle
    await self._async_websocket_command_phase(connection)
  File "/usr/src/homeassistant/homeassistant/components/websocket_api/http.py", line 463, in _async_websocket_command_phase
    msg = await wsock.receive()
          ^^^^^^^^^^^^^^^^^^^^^
  File "/usr/local/lib/python3.13/site-packages/aiohttp/web_ws.py", line 575, in receive
    await self.pong(msg.data)
  File "/usr/local/lib/python3.13/site-packages/aiohttp/web_ws.py", line 393, in pong
    await self._writer.send_frame(message, WSMsgType.PONG)
  File "/usr/local/lib/python3.13/site-packages/aiohttp/_websocket/writer.py", line 125, in send_frame
    raise ClientConnectionResetError("Cannot write to closing transport")
aiohttp.client_exceptions.ClientConnectionResetError: Cannot write to closing transport
2025-01-12 11:13:05.650 ERROR (MainThread) [homeassistant.components.websocket_api.http.connection] [140124420630432] Supervisor from 172.30.32.2 (HomeAssistantSupervisor/2024.12.3 aiohttp/3.11.11 Python/3.12): Unexpected error inside websocket API
Traceback (most recent call last):
  File "/usr/src/homeassistant/homeassistant/components/websocket_api/http.py", line 343, in async_handle
    await self._async_websocket_command_phase(connection)
  File "/usr/src/homeassistant/homeassistant/components/websocket_api/http.py", line 463, in _async_websocket_command_phase
    msg = await wsock.receive()
          ^^^^^^^^^^^^^^^^^^^^^
  File "/usr/local/lib/python3.13/site-packages/aiohttp/web_ws.py", line 575, in receive
    await self.pong(msg.data)
  File "/usr/local/lib/python3.13/site-packages/aiohttp/web_ws.py", line 393, in pong
    await self._writer.send_frame(message, WSMsgType.PONG)
  File "/usr/local/lib/python3.13/site-packages/aiohttp/_websocket/writer.py", line 125, in send_frame
    raise ClientConnectionResetError("Cannot write to closing transport")
aiohttp.client_exceptions.ClientConnectionResetError: Cannot write to closing transport
2025-01-12 11:13:05.651 ERROR (MainThread) [homeassistant.components.websocket_api.http.connection] [140124438686464] Supervisor from 172.30.32.2 (HomeAssistantSupervisor/2024.12.3 aiohttp/3.11.11 Python/3.12): Unexpected error inside websocket API
Traceback (most recent call last):
  File "/usr/src/homeassistant/homeassistant/components/websocket_api/http.py", line 343, in async_handle
    await self._async_websocket_command_phase(connection)
  File "/usr/src/homeassistant/homeassistant/components/websocket_api/http.py", line 463, in _async_websocket_command_phase
    msg = await wsock.receive()
          ^^^^^^^^^^^^^^^^^^^^^
  File "/usr/local/lib/python3.13/site-packages/aiohttp/web_ws.py", line 575, in receive
    await self.pong(msg.data)
  File "/usr/local/lib/python3.13/site-packages/aiohttp/web_ws.py", line 393, in pong
    await self._writer.send_frame(message, WSMsgType.PONG)
  File "/usr/local/lib/python3.13/site-packages/aiohttp/_websocket/writer.py", line 125, in send_frame
    raise ClientConnectionResetError("Cannot write to closing transport")
aiohttp.client_exceptions.ClientConnectionResetError: Cannot write to closing transport
2025-01-12 11:13:05.653 ERROR (MainThread) [homeassistant.components.websocket_api.http.connection] [140124438690496] Supervisor from 172.30.32.2 (HomeAssistantSupervisor/2024.12.3 aiohttp/3.11.11 Python/3.12): Unexpected error inside websocket API
Traceback (most recent call last):
  File "/usr/src/homeassistant/homeassistant/components/websocket_api/http.py", line 343, in async_handle
    await self._async_websocket_command_phase(connection)
  File "/usr/src/homeassistant/homeassistant/components/websocket_api/http.py", line 463, in _async_websocket_command_phase
    msg = await wsock.receive()
          ^^^^^^^^^^^^^^^^^^^^^
  File "/usr/local/lib/python3.13/site-packages/aiohttp/web_ws.py", line 575, in receive
    await self.pong(msg.data)
  File "/usr/local/lib/python3.13/site-packages/aiohttp/web_ws.py", line 393, in pong
    await self._writer.send_frame(message, WSMsgType.PONG)
  File "/usr/local/lib/python3.13/site-packages/aiohttp/_websocket/writer.py", line 125, in send_frame
    raise ClientConnectionResetError("Cannot write to closing transport")
aiohttp.client_exceptions.ClientConnectionResetError: Cannot write to closing transport
2025-01-12 11:13:05.654 ERROR (MainThread) [homeassistant.components.websocket_api.http.connection] [140124438688048] Supervisor from 172.30.32.2 (HomeAssistantSupervisor/2024.12.3 aiohttp/3.11.11 Python/3.12): Unexpected error inside websocket API
Traceback (most recent call last):
  File "/usr/src/homeassistant/homeassistant/components/websocket_api/http.py", line 343, in async_handle
    await self._async_websocket_command_phase(connection)
  File "/usr/src/homeassistant/homeassistant/components/websocket_api/http.py", line 463, in _async_websocket_command_phase
    msg = await wsock.receive()
          ^^^^^^^^^^^^^^^^^^^^^
  File "/usr/local/lib/python3.13/site-packages/aiohttp/web_ws.py", line 575, in receive
    await self.pong(msg.data)
  File "/usr/local/lib/python3.13/site-packages/aiohttp/web_ws.py", line 393, in pong
    await self._writer.send_frame(message, WSMsgType.PONG)
  File "/usr/local/lib/python3.13/site-packages/aiohttp/_websocket/writer.py", line 125, in send_frame
    raise ClientConnectionResetError("Cannot write to closing transport")
aiohttp.client_exceptions.ClientConnectionResetError: Cannot write to closing transport
2025-01-12 11:14:27.670 ERROR (Recorder) [homeassistant.components.recorder.core] Database connection invalidated: Error executing query: (MySQLdb.OperationalError) (2013, 'Lost connection to server during query')
[SQL: UPDATE states SET last_reported_ts=%s WHERE states.state_id = %s]
[parameters: (1736698451.9052577, 60895)]
(Background on this error at: https://sqlalche.me/e/20/e3q8). (retrying in 3 seconds)
2025-01-12 11:14:30.677 ERROR (Recorder) [homeassistant.components.recorder.core] SQLAlchemyError error processing task CommitTask()
Traceback (most recent call last):
  File "/usr/src/homeassistant/homeassistant/components/recorder/core.py", line 894, in _process_one_task_or_event_or_recover
    task.run(self)
    ~~~~~~~~^^^^^^
  File "/usr/src/homeassistant/homeassistant/components/recorder/tasks.py", line 295, in run
    instance._commit_event_session_or_retry()  # noqa: SLF001
    ~~~~~~~~~~~~~~~~~~~~~~~~~~~~~~~~~~~~~~~^^
  File "/usr/src/homeassistant/homeassistant/components/recorder/core.py", line 1193, in _commit_event_session_or_retry
    self._commit_event_session()
    ~~~~~~~~~~~~~~~~~~~~~~~~~~^^
  File "/usr/src/homeassistant/homeassistant/components/recorder/core.py", line 1219, in _commit_event_session
    session.execute(
    ~~~~~~~~~~~~~~~^
        update(States),
        ^^^^^^^^^^^^^^^
    ...<6 lines>...
        ],
        ^^
    )
    ^
  File "/usr/local/lib/python3.13/site-packages/sqlalchemy/orm/session.py", line 2362, in execute
    return self._execute_internal(
           ~~~~~~~~~~~~~~~~~~~~~~^
        statement,
        ^^^^^^^^^^
    ...<4 lines>...
        _add_event=_add_event,
        ^^^^^^^^^^^^^^^^^^^^^^
    )
    ^
  File "/usr/local/lib/python3.13/site-packages/sqlalchemy/orm/session.py", line 2247, in _execute_internal
    result: Result[Any] = compile_state_cls.orm_execute_statement(
                          ~~~~~~~~~~~~~~~~~~~~~~~~~~~~~~~~~~~~~~~^
        self,
        ^^^^^
    ...<4 lines>...
        conn,
        ^^^^^
    )
    ^
  File "/usr/local/lib/python3.13/site-packages/sqlalchemy/orm/bulk_persistence.py", line 1627, in orm_execute_statement
    result = _bulk_update(
        mapper,
    ...<8 lines>...
        enable_check_rowcount=enable_check_rowcount,
    )
  File "/usr/local/lib/python3.13/site-packages/sqlalchemy/orm/bulk_persistence.py", line 357, in _bulk_update
    persistence._emit_update_statements(
    ~~~~~~~~~~~~~~~~~~~~~~~~~~~~~~~~~~~^
        base_mapper,
        ^^^^^^^^^^^^
    ...<6 lines>...
        enable_check_rowcount=enable_check_rowcount,
        ^^^^^^^^^^^^^^^^^^^^^^^^^^^^^^^^^^^^^^^^^^^^
    )
    ^
  File "/usr/local/lib/python3.13/site-packages/sqlalchemy/orm/persistence.py", line 912, in _emit_update_statements
    c = connection.execute(
        statement, multiparams, execution_options=execution_options
    )
  File "/usr/local/lib/python3.13/site-packages/sqlalchemy/engine/base.py", line 1418, in execute
    return meth(
        self,
        distilled_parameters,
        execution_options or NO_OPTIONS,
    )
  File "/usr/local/lib/python3.13/site-packages/sqlalchemy/sql/elements.py", line 515, in _execute_on_connection
    return connection._execute_clauseelement(
           ~~~~~~~~~~~~~~~~~~~~~~~~~~~~~~~~~^
        self, distilled_params, execution_options
        ^^^^^^^^^^^^^^^^^^^^^^^^^^^^^^^^^^^^^^^^^
    )
    ^
  File "/usr/local/lib/python3.13/site-packages/sqlalchemy/engine/base.py", line 1640, in _execute_clauseelement
    ret = self._execute_context(
        dialect,
    ...<8 lines>...
        cache_hit=cache_hit,
    )
  File "/usr/local/lib/python3.13/site-packages/sqlalchemy/engine/base.py", line 1813, in _execute_context
    conn = self._revalidate_connection()
  File "/usr/local/lib/python3.13/site-packages/sqlalchemy/engine/base.py", line 677, in _revalidate_connection
    self._invalid_transaction()
    ~~~~~~~~~~~~~~~~~~~~~~~~~^^
  File "/usr/local/lib/python3.13/site-packages/sqlalchemy/engine/base.py", line 667, in _invalid_transaction
    raise exc.PendingRollbackError(
    ...<4 lines>...
    )
sqlalchemy.exc.PendingRollbackError: Can't reconnect until invalid transaction is rolled back.  Please rollback() fully before proceeding (Background on this error at: https://sqlalche.me/e/20/8s2b)
2025-01-12 11:14:31.683 ERROR (MainThread) [snitun.multiplexer.core] Ping fails, no response from peer
2025-01-12 11:56:00.344 ERROR (MainThread) [homeassistant.components.automation.collect_bird_buddy_postcard] Collect Bird Buddy Postcard: Error executing script. Invalid data for call_service at pos 1: value should be a string for dictionary value @ data['device_id']
2025-01-12 11:56:00.344 ERROR (MainThread) [homeassistant.components.automation.collect_bird_buddy_postcard] Error while executing automation automation.collect_bird_buddy_postcard: value should be a string for dictionary value @ data['device_id']
2025-01-12 11:59:39.166 ERROR (MainThread) [homeassistant.components.websocket_api.http.connection] [140124288533696] Error handling message: Unauthorized (unauthorized) Candy from 192.168.87.1 (Mozilla/5.0 (iPhone; CPU iPhone OS 18_1_1 like Mac OS X) AppleWebKit/605.1.15 (KHTML, like Gecko) Home Assistant/2024.12.2 (io.robbie.HomeAssistant; build:2024.1058; iOS 18.1.1) Mobile/HomeAssistant, like Safari)
2025-01-12 11:59:39.166 ERROR (MainThread) [homeassistant.components.websocket_api.commands] Refusing to allow Candy to subscribe to event call_service
2025-01-12 11:59:39.167 ERROR (MainThread) [homeassistant.components.websocket_api.http.connection] [140124288533696] Error handling message: Unauthorized (unauthorized) Candy from 192.168.87.1 (Mozilla/5.0 (iPhone; CPU iPhone OS 18_1_1 like Mac OS X) AppleWebKit/605.1.15 (KHTML, like Gecko) Home Assistant/2024.12.2 (io.robbie.HomeAssistant; build:2024.1058; iOS 18.1.1) Mobile/HomeAssistant, like Safari)
2025-01-12 12:36:05.424 ERROR (MainThread) [homeassistant.components.automation.collect_bird_buddy_postcard] Collect Bird Buddy Postcard: Error executing script. Invalid data for call_service at pos 1: value should be a string for dictionary value @ data['device_id']
2025-01-12 12:36:05.424 ERROR (MainThread) [homeassistant.components.automation.collect_bird_buddy_postcard] Error while executing automation automation.collect_bird_buddy_postcard: value should be a string for dictionary value @ data['device_id']
2025-01-12 13:06:09.828 ERROR (MainThread) [homeassistant.components.automation.collect_bird_buddy_postcard] Collect Bird Buddy Postcard: Error executing script. Invalid data for call_service at pos 1: value should be a string for dictionary value @ data['device_id']
2025-01-12 13:06:09.829 ERROR (MainThread) [homeassistant.components.automation.collect_bird_buddy_postcard] Error while executing automation automation.collect_bird_buddy_postcard: value should be a string for dictionary value @ data['device_id']
2025-01-12 13:22:15.752 ERROR (MainThread) [homeassistant.components.script.announce_candy_has_arrived] Announce - Candy Has Arrived: Error executing script. Invalid data for call_service at pos 5: expected float for dictionary value @ data['volume_level']
2025-01-12 13:22:15.754 ERROR (MainThread) [homeassistant.components.automation.announce_candy_has_arrived] Announce - Candy Has Arrived: Error executing script. Invalid data for call_service at pos 1: expected float for dictionary value @ data['volume_level']
2025-01-12 13:22:15.755 ERROR (MainThread) [homeassistant.components.automation.announce_candy_has_arrived] Error while executing automation automation.announce_candy_has_arrived: expected float for dictionary value @ data['volume_level']
2025-01-12 14:04:37.547 ERROR (MainThread) [homeassistant] Error doing job: Task exception was never retrieved (None)
Traceback (most recent call last):
  File "/usr/src/homeassistant/homeassistant/helpers/update_coordinator.py", line 267, in _handle_refresh_interval
    await self._async_refresh(log_failures=True, scheduled=True)
  File "/usr/src/homeassistant/homeassistant/helpers/update_coordinator.py", line 478, in _async_refresh
    self.async_update_listeners()
    ~~~~~~~~~~~~~~~~~~~~~~~~~~~^^
  File "/usr/src/homeassistant/homeassistant/helpers/update_coordinator.py", line 177, in async_update_listeners
    update_callback()
    ~~~~~~~~~~~~~~~^^
  File "/usr/src/homeassistant/homeassistant/components/tesla_fleet/entity.py", line 83, in _handle_coordinator_update
    self._async_update_attrs()
    ~~~~~~~~~~~~~~~~~~~~~~~~^^
  File "/usr/src/homeassistant/homeassistant/components/tesla_fleet/select.py", line 188, in _async_update_attrs
    self._attr_current_option = self._attr_options[value]
                                ~~~~~~~~~~~~~~~~~~^^^^^^^
IndexError: list index out of range
2025-01-12 14:06:18.183 ERROR (MainThread) [homeassistant] Error doing job: Task exception was never retrieved (None)
Traceback (most recent call last):
  File "/usr/src/homeassistant/homeassistant/helpers/update_coordinator.py", line 267, in _handle_refresh_interval
    await self._async_refresh(log_failures=True, scheduled=True)
  File "/usr/src/homeassistant/homeassistant/helpers/update_coordinator.py", line 478, in _async_refresh
    self.async_update_listeners()
    ~~~~~~~~~~~~~~~~~~~~~~~~~~~^^
  File "/usr/src/homeassistant/homeassistant/helpers/update_coordinator.py", line 177, in async_update_listeners
    update_callback()
    ~~~~~~~~~~~~~~~^^
  File "/usr/src/homeassistant/homeassistant/components/tesla_fleet/entity.py", line 83, in _handle_coordinator_update
    self._async_update_attrs()
    ~~~~~~~~~~~~~~~~~~~~~~~~^^
  File "/usr/src/homeassistant/homeassistant/components/tesla_fleet/select.py", line 188, in _async_update_attrs
    self._attr_current_option = self._attr_options[value]
                                ~~~~~~~~~~~~~~~~~~^^^^^^^
IndexError: list index out of range
2025-01-12 14:07:59.528 ERROR (MainThread) [homeassistant] Error doing job: Task exception was never retrieved (None)
Traceback (most recent call last):
  File "/usr/src/homeassistant/homeassistant/helpers/update_coordinator.py", line 267, in _handle_refresh_interval
    await self._async_refresh(log_failures=True, scheduled=True)
  File "/usr/src/homeassistant/homeassistant/helpers/update_coordinator.py", line 478, in _async_refresh
    self.async_update_listeners()
    ~~~~~~~~~~~~~~~~~~~~~~~~~~~^^
  File "/usr/src/homeassistant/homeassistant/helpers/update_coordinator.py", line 177, in async_update_listeners
    update_callback()
    ~~~~~~~~~~~~~~~^^
  File "/usr/src/homeassistant/homeassistant/components/tesla_fleet/entity.py", line 83, in _handle_coordinator_update
    self._async_update_attrs()
    ~~~~~~~~~~~~~~~~~~~~~~~~^^
  File "/usr/src/homeassistant/homeassistant/components/tesla_fleet/select.py", line 188, in _async_update_attrs
    self._attr_current_option = self._attr_options[value]
                                ~~~~~~~~~~~~~~~~~~^^^^^^^
IndexError: list index out of range
2025-01-12 14:09:41.144 ERROR (MainThread) [homeassistant] Error doing job: Task exception was never retrieved (None)
Traceback (most recent call last):
  File "/usr/src/homeassistant/homeassistant/helpers/update_coordinator.py", line 267, in _handle_refresh_interval
    await self._async_refresh(log_failures=True, scheduled=True)
  File "/usr/src/homeassistant/homeassistant/helpers/update_coordinator.py", line 478, in _async_refresh
    self.async_update_listeners()
    ~~~~~~~~~~~~~~~~~~~~~~~~~~~^^
  File "/usr/src/homeassistant/homeassistant/helpers/update_coordinator.py", line 177, in async_update_listeners
    update_callback()
    ~~~~~~~~~~~~~~~^^
  File "/usr/src/homeassistant/homeassistant/components/tesla_fleet/entity.py", line 83, in _handle_coordinator_update
    self._async_update_attrs()
    ~~~~~~~~~~~~~~~~~~~~~~~~^^
  File "/usr/src/homeassistant/homeassistant/components/tesla_fleet/select.py", line 188, in _async_update_attrs
    self._attr_current_option = self._attr_options[value]
                                ~~~~~~~~~~~~~~~~~~^^^^^^^
IndexError: list index out of range
2025-01-12 14:11:23.845 ERROR (MainThread) [homeassistant] Error doing job: Task exception was never retrieved (None)
Traceback (most recent call last):
  File "/usr/src/homeassistant/homeassistant/helpers/update_coordinator.py", line 267, in _handle_refresh_interval
    await self._async_refresh(log_failures=True, scheduled=True)
  File "/usr/src/homeassistant/homeassistant/helpers/update_coordinator.py", line 478, in _async_refresh
    self.async_update_listeners()
    ~~~~~~~~~~~~~~~~~~~~~~~~~~~^^
  File "/usr/src/homeassistant/homeassistant/helpers/update_coordinator.py", line 177, in async_update_listeners
    update_callback()
    ~~~~~~~~~~~~~~~^^
  File "/usr/src/homeassistant/homeassistant/components/tesla_fleet/entity.py", line 83, in _handle_coordinator_update
    self._async_update_attrs()
    ~~~~~~~~~~~~~~~~~~~~~~~~^^
  File "/usr/src/homeassistant/homeassistant/components/tesla_fleet/select.py", line 188, in _async_update_attrs
    self._attr_current_option = self._attr_options[value]
                                ~~~~~~~~~~~~~~~~~~^^^^^^^
IndexError: list index out of range
2025-01-12 14:13:07.337 ERROR (MainThread) [homeassistant] Error doing job: Task exception was never retrieved (None)
Traceback (most recent call last):
  File "/usr/src/homeassistant/homeassistant/helpers/update_coordinator.py", line 267, in _handle_refresh_interval
    await self._async_refresh(log_failures=True, scheduled=True)
  File "/usr/src/homeassistant/homeassistant/helpers/update_coordinator.py", line 478, in _async_refresh
    self.async_update_listeners()
    ~~~~~~~~~~~~~~~~~~~~~~~~~~~^^
  File "/usr/src/homeassistant/homeassistant/helpers/update_coordinator.py", line 177, in async_update_listeners
    update_callback()
    ~~~~~~~~~~~~~~~^^
  File "/usr/src/homeassistant/homeassistant/components/tesla_fleet/entity.py", line 83, in _handle_coordinator_update
    self._async_update_attrs()
    ~~~~~~~~~~~~~~~~~~~~~~~~^^
  File "/usr/src/homeassistant/homeassistant/components/tesla_fleet/select.py", line 188, in _async_update_attrs
    self._attr_current_option = self._attr_options[value]
                                ~~~~~~~~~~~~~~~~~~^^^^^^^
IndexError: list index out of range
2025-01-12 14:14:51.004 ERROR (MainThread) [homeassistant] Error doing job: Task exception was never retrieved (None)
Traceback (most recent call last):
  File "/usr/src/homeassistant/homeassistant/helpers/update_coordinator.py", line 267, in _handle_refresh_interval
    await self._async_refresh(log_failures=True, scheduled=True)
  File "/usr/src/homeassistant/homeassistant/helpers/update_coordinator.py", line 478, in _async_refresh
    self.async_update_listeners()
    ~~~~~~~~~~~~~~~~~~~~~~~~~~~^^
  File "/usr/src/homeassistant/homeassistant/helpers/update_coordinator.py", line 177, in async_update_listeners
    update_callback()
    ~~~~~~~~~~~~~~~^^
  File "/usr/src/homeassistant/homeassistant/components/tesla_fleet/entity.py", line 83, in _handle_coordinator_update
    self._async_update_attrs()
    ~~~~~~~~~~~~~~~~~~~~~~~~^^
  File "/usr/src/homeassistant/homeassistant/components/tesla_fleet/select.py", line 188, in _async_update_attrs
    self._attr_current_option = self._attr_options[value]
                                ~~~~~~~~~~~~~~~~~~^^^^^^^
IndexError: list index out of range
2025-01-12 14:16:18.447 ERROR (MainThread) [homeassistant.components.automation.collect_bird_buddy_postcard] Collect Bird Buddy Postcard: Error executing script. Invalid data for call_service at pos 1: value should be a string for dictionary value @ data['device_id']
2025-01-12 14:16:18.447 ERROR (MainThread) [homeassistant.components.automation.collect_bird_buddy_postcard] Error while executing automation automation.collect_bird_buddy_postcard: value should be a string for dictionary value @ data['device_id']
2025-01-12 14:16:35.569 ERROR (MainThread) [homeassistant] Error doing job: Task exception was never retrieved (None)
Traceback (most recent call last):
  File "/usr/src/homeassistant/homeassistant/helpers/update_coordinator.py", line 267, in _handle_refresh_interval
    await self._async_refresh(log_failures=True, scheduled=True)
  File "/usr/src/homeassistant/homeassistant/helpers/update_coordinator.py", line 478, in _async_refresh
    self.async_update_listeners()
    ~~~~~~~~~~~~~~~~~~~~~~~~~~~^^
  File "/usr/src/homeassistant/homeassistant/helpers/update_coordinator.py", line 177, in async_update_listeners
    update_callback()
    ~~~~~~~~~~~~~~~^^
  File "/usr/src/homeassistant/homeassistant/components/tesla_fleet/entity.py", line 83, in _handle_coordinator_update
    self._async_update_attrs()
    ~~~~~~~~~~~~~~~~~~~~~~~~^^
  File "/usr/src/homeassistant/homeassistant/components/tesla_fleet/select.py", line 188, in _async_update_attrs
    self._attr_current_option = self._attr_options[value]
                                ~~~~~~~~~~~~~~~~~~^^^^^^^
IndexError: list index out of range
2025-01-12 14:18:20.160 ERROR (MainThread) [homeassistant] Error doing job: Task exception was never retrieved (None)
Traceback (most recent call last):
  File "/usr/src/homeassistant/homeassistant/helpers/update_coordinator.py", line 267, in _handle_refresh_interval
    await self._async_refresh(log_failures=True, scheduled=True)
  File "/usr/src/homeassistant/homeassistant/helpers/update_coordinator.py", line 478, in _async_refresh
    self.async_update_listeners()
    ~~~~~~~~~~~~~~~~~~~~~~~~~~~^^
  File "/usr/src/homeassistant/homeassistant/helpers/update_coordinator.py", line 177, in async_update_listeners
    update_callback()
    ~~~~~~~~~~~~~~~^^
  File "/usr/src/homeassistant/homeassistant/components/tesla_fleet/entity.py", line 83, in _handle_coordinator_update
    self._async_update_attrs()
    ~~~~~~~~~~~~~~~~~~~~~~~~^^
  File "/usr/src/homeassistant/homeassistant/components/tesla_fleet/select.py", line 188, in _async_update_attrs
    self._attr_current_option = self._attr_options[value]
                                ~~~~~~~~~~~~~~~~~~^^^^^^^
IndexError: list index out of range
2025-01-12 14:20:05.818 ERROR (MainThread) [homeassistant] Error doing job: Task exception was never retrieved (None)
Traceback (most recent call last):
  File "/usr/src/homeassistant/homeassistant/helpers/update_coordinator.py", line 267, in _handle_refresh_interval
    await self._async_refresh(log_failures=True, scheduled=True)
  File "/usr/src/homeassistant/homeassistant/helpers/update_coordinator.py", line 478, in _async_refresh
    self.async_update_listeners()
    ~~~~~~~~~~~~~~~~~~~~~~~~~~~^^
  File "/usr/src/homeassistant/homeassistant/helpers/update_coordinator.py", line 177, in async_update_listeners
    update_callback()
    ~~~~~~~~~~~~~~~^^
  File "/usr/src/homeassistant/homeassistant/components/tesla_fleet/entity.py", line 83, in _handle_coordinator_update
    self._async_update_attrs()
    ~~~~~~~~~~~~~~~~~~~~~~~~^^
  File "/usr/src/homeassistant/homeassistant/components/tesla_fleet/select.py", line 188, in _async_update_attrs
    self._attr_current_option = self._attr_options[value]
                                ~~~~~~~~~~~~~~~~~~^^^^^^^
IndexError: list index out of range
2025-01-12 14:21:52.447 ERROR (MainThread) [homeassistant] Error doing job: Task exception was never retrieved (None)
Traceback (most recent call last):
  File "/usr/src/homeassistant/homeassistant/helpers/update_coordinator.py", line 267, in _handle_refresh_interval
    await self._async_refresh(log_failures=True, scheduled=True)
  File "/usr/src/homeassistant/homeassistant/helpers/update_coordinator.py", line 478, in _async_refresh
    self.async_update_listeners()
    ~~~~~~~~~~~~~~~~~~~~~~~~~~~^^
  File "/usr/src/homeassistant/homeassistant/helpers/update_coordinator.py", line 177, in async_update_listeners
    update_callback()
    ~~~~~~~~~~~~~~~^^
  File "/usr/src/homeassistant/homeassistant/components/tesla_fleet/entity.py", line 83, in _handle_coordinator_update
    self._async_update_attrs()
    ~~~~~~~~~~~~~~~~~~~~~~~~^^
  File "/usr/src/homeassistant/homeassistant/components/tesla_fleet/select.py", line 188, in _async_update_attrs
    self._attr_current_option = self._attr_options[value]
                                ~~~~~~~~~~~~~~~~~~^^^^^^^
IndexError: list index out of range
2025-01-12 14:23:39.096 ERROR (MainThread) [homeassistant] Error doing job: Task exception was never retrieved (None)
Traceback (most recent call last):
  File "/usr/src/homeassistant/homeassistant/helpers/update_coordinator.py", line 267, in _handle_refresh_interval
    await self._async_refresh(log_failures=True, scheduled=True)
  File "/usr/src/homeassistant/homeassistant/helpers/update_coordinator.py", line 478, in _async_refresh
    self.async_update_listeners()
    ~~~~~~~~~~~~~~~~~~~~~~~~~~~^^
  File "/usr/src/homeassistant/homeassistant/helpers/update_coordinator.py", line 177, in async_update_listeners
    update_callback()
    ~~~~~~~~~~~~~~~^^
  File "/usr/src/homeassistant/homeassistant/components/tesla_fleet/entity.py", line 83, in _handle_coordinator_update
    self._async_update_attrs()
    ~~~~~~~~~~~~~~~~~~~~~~~~^^
  File "/usr/src/homeassistant/homeassistant/components/tesla_fleet/select.py", line 188, in _async_update_attrs
    self._attr_current_option = self._attr_options[value]
                                ~~~~~~~~~~~~~~~~~~^^^^^^^
IndexError: list index out of range
2025-01-12 14:25:26.783 ERROR (MainThread) [homeassistant] Error doing job: Task exception was never retrieved (None)
Traceback (most recent call last):
  File "/usr/src/homeassistant/homeassistant/helpers/update_coordinator.py", line 267, in _handle_refresh_interval
    await self._async_refresh(log_failures=True, scheduled=True)
  File "/usr/src/homeassistant/homeassistant/helpers/update_coordinator.py", line 478, in _async_refresh
    self.async_update_listeners()
    ~~~~~~~~~~~~~~~~~~~~~~~~~~~^^
  File "/usr/src/homeassistant/homeassistant/helpers/update_coordinator.py", line 177, in async_update_listeners
    update_callback()
    ~~~~~~~~~~~~~~~^^
  File "/usr/src/homeassistant/homeassistant/components/tesla_fleet/entity.py", line 83, in _handle_coordinator_update
    self._async_update_attrs()
    ~~~~~~~~~~~~~~~~~~~~~~~~^^
  File "/usr/src/homeassistant/homeassistant/components/tesla_fleet/select.py", line 188, in _async_update_attrs
    self._attr_current_option = self._attr_options[value]
                                ~~~~~~~~~~~~~~~~~~^^^^^^^
IndexError: list index out of range
2025-01-12 14:27:15.460 ERROR (MainThread) [homeassistant] Error doing job: Task exception was never retrieved (None)
Traceback (most recent call last):
  File "/usr/src/homeassistant/homeassistant/helpers/update_coordinator.py", line 267, in _handle_refresh_interval
    await self._async_refresh(log_failures=True, scheduled=True)
  File "/usr/src/homeassistant/homeassistant/helpers/update_coordinator.py", line 478, in _async_refresh
    self.async_update_listeners()
    ~~~~~~~~~~~~~~~~~~~~~~~~~~~^^
  File "/usr/src/homeassistant/homeassistant/helpers/update_coordinator.py", line 177, in async_update_listeners
    update_callback()
    ~~~~~~~~~~~~~~~^^
  File "/usr/src/homeassistant/homeassistant/components/tesla_fleet/entity.py", line 83, in _handle_coordinator_update
    self._async_update_attrs()
    ~~~~~~~~~~~~~~~~~~~~~~~~^^
  File "/usr/src/homeassistant/homeassistant/components/tesla_fleet/select.py", line 188, in _async_update_attrs
    self._attr_current_option = self._attr_options[value]
                                ~~~~~~~~~~~~~~~~~~^^^^^^^
IndexError: list index out of range
2025-01-12 14:29:04.185 ERROR (MainThread) [homeassistant] Error doing job: Task exception was never retrieved (None)
Traceback (most recent call last):
  File "/usr/src/homeassistant/homeassistant/helpers/update_coordinator.py", line 267, in _handle_refresh_interval
    await self._async_refresh(log_failures=True, scheduled=True)
  File "/usr/src/homeassistant/homeassistant/helpers/update_coordinator.py", line 478, in _async_refresh
    self.async_update_listeners()
    ~~~~~~~~~~~~~~~~~~~~~~~~~~~^^
  File "/usr/src/homeassistant/homeassistant/helpers/update_coordinator.py", line 177, in async_update_listeners
    update_callback()
    ~~~~~~~~~~~~~~~^^
  File "/usr/src/homeassistant/homeassistant/components/tesla_fleet/entity.py", line 83, in _handle_coordinator_update
    self._async_update_attrs()
    ~~~~~~~~~~~~~~~~~~~~~~~~^^
  File "/usr/src/homeassistant/homeassistant/components/tesla_fleet/select.py", line 188, in _async_update_attrs
    self._attr_current_option = self._attr_options[value]
                                ~~~~~~~~~~~~~~~~~~^^^^^^^
IndexError: list index out of range
2025-01-12 14:30:53.852 ERROR (MainThread) [homeassistant] Error doing job: Task exception was never retrieved (None)
Traceback (most recent call last):
  File "/usr/src/homeassistant/homeassistant/helpers/update_coordinator.py", line 267, in _handle_refresh_interval
    await self._async_refresh(log_failures=True, scheduled=True)
  File "/usr/src/homeassistant/homeassistant/helpers/update_coordinator.py", line 478, in _async_refresh
    self.async_update_listeners()
    ~~~~~~~~~~~~~~~~~~~~~~~~~~~^^
  File "/usr/src/homeassistant/homeassistant/helpers/update_coordinator.py", line 177, in async_update_listeners
    update_callback()
    ~~~~~~~~~~~~~~~^^
  File "/usr/src/homeassistant/homeassistant/components/tesla_fleet/entity.py", line 83, in _handle_coordinator_update
    self._async_update_attrs()
    ~~~~~~~~~~~~~~~~~~~~~~~~^^
  File "/usr/src/homeassistant/homeassistant/components/tesla_fleet/select.py", line 188, in _async_update_attrs
    self._attr_current_option = self._attr_options[value]
                                ~~~~~~~~~~~~~~~~~~^^^^^^^
IndexError: list index out of range
2025-01-12 14:32:31.241 ERROR (MainThread) [homeassistant.components.websocket_api.http.connection] [140124278131296] Supervisor from 172.30.32.2 (HomeAssistantSupervisor/2024.12.3 aiohttp/3.11.11 Python/3.12): Unexpected error inside websocket API
Traceback (most recent call last):
  File "/usr/src/homeassistant/homeassistant/components/websocket_api/http.py", line 343, in async_handle
    await self._async_websocket_command_phase(connection)
  File "/usr/src/homeassistant/homeassistant/components/websocket_api/http.py", line 463, in _async_websocket_command_phase
    msg = await wsock.receive()
          ^^^^^^^^^^^^^^^^^^^^^
  File "/usr/local/lib/python3.13/site-packages/aiohttp/web_ws.py", line 575, in receive
    await self.pong(msg.data)
  File "/usr/local/lib/python3.13/site-packages/aiohttp/web_ws.py", line 393, in pong
    await self._writer.send_frame(message, WSMsgType.PONG)
  File "/usr/local/lib/python3.13/site-packages/aiohttp/_websocket/writer.py", line 125, in send_frame
    raise ClientConnectionResetError("Cannot write to closing transport")
aiohttp.client_exceptions.ClientConnectionResetError: Cannot write to closing transport
2025-01-12 14:32:31.895 ERROR (MainThread) [homeassistant.components.websocket_api.http.connection] [140124387603744] Supervisor from 172.30.32.2 (HomeAssistantSupervisor/2024.12.3 aiohttp/3.11.11 Python/3.12): Unexpected error inside websocket API
Traceback (most recent call last):
  File "/usr/src/homeassistant/homeassistant/components/websocket_api/http.py", line 343, in async_handle
    await self._async_websocket_command_phase(connection)
  File "/usr/src/homeassistant/homeassistant/components/websocket_api/http.py", line 463, in _async_websocket_command_phase
    msg = await wsock.receive()
          ^^^^^^^^^^^^^^^^^^^^^
  File "/usr/local/lib/python3.13/site-packages/aiohttp/web_ws.py", line 575, in receive
    await self.pong(msg.data)
  File "/usr/local/lib/python3.13/site-packages/aiohttp/web_ws.py", line 393, in pong
    await self._writer.send_frame(message, WSMsgType.PONG)
  File "/usr/local/lib/python3.13/site-packages/aiohttp/_websocket/writer.py", line 125, in send_frame
    raise ClientConnectionResetError("Cannot write to closing transport")
aiohttp.client_exceptions.ClientConnectionResetError: Cannot write to closing transport
2025-01-12 14:32:31.905 ERROR (MainThread) [homeassistant.components.websocket_api.http.connection] [140124288538016] Supervisor from 172.30.32.2 (HomeAssistantSupervisor/2024.12.3 aiohttp/3.11.11 Python/3.12): Unexpected error inside websocket API
Traceback (most recent call last):
  File "/usr/src/homeassistant/homeassistant/components/websocket_api/http.py", line 343, in async_handle
    await self._async_websocket_command_phase(connection)
  File "/usr/src/homeassistant/homeassistant/components/websocket_api/http.py", line 463, in _async_websocket_command_phase
    msg = await wsock.receive()
          ^^^^^^^^^^^^^^^^^^^^^
  File "/usr/local/lib/python3.13/site-packages/aiohttp/web_ws.py", line 575, in receive
    await self.pong(msg.data)
  File "/usr/local/lib/python3.13/site-packages/aiohttp/web_ws.py", line 393, in pong
    await self._writer.send_frame(message, WSMsgType.PONG)
  File "/usr/local/lib/python3.13/site-packages/aiohttp/_websocket/writer.py", line 125, in send_frame
    raise ClientConnectionResetError("Cannot write to closing transport")
aiohttp.client_exceptions.ClientConnectionResetError: Cannot write to closing transport
2025-01-12 14:32:31.909 ERROR (MainThread) [homeassistant.components.websocket_api.http.connection] [140124288545648] Supervisor from 172.30.32.2 (HomeAssistantSupervisor/2024.12.3 aiohttp/3.11.11 Python/3.12): Unexpected error inside websocket API
Traceback (most recent call last):
  File "/usr/src/homeassistant/homeassistant/components/websocket_api/http.py", line 343, in async_handle
    await self._async_websocket_command_phase(connection)
  File "/usr/src/homeassistant/homeassistant/components/websocket_api/http.py", line 463, in _async_websocket_command_phase
    msg = await wsock.receive()
          ^^^^^^^^^^^^^^^^^^^^^
  File "/usr/local/lib/python3.13/site-packages/aiohttp/web_ws.py", line 575, in receive
    await self.pong(msg.data)
  File "/usr/local/lib/python3.13/site-packages/aiohttp/web_ws.py", line 393, in pong
    await self._writer.send_frame(message, WSMsgType.PONG)
  File "/usr/local/lib/python3.13/site-packages/aiohttp/_websocket/writer.py", line 125, in send_frame
    raise ClientConnectionResetError("Cannot write to closing transport")
aiohttp.client_exceptions.ClientConnectionResetError: Cannot write to closing transport
2025-01-12 14:32:32.348 ERROR (MainThread) [homeassistant.components.ipp.coordinator] Error fetching ipp data: Invalid response from API: Timeout occurred while connecting to IPP server.
2025-01-12 14:32:44.596 ERROR (MainThread) [homeassistant] Error doing job: Task exception was never retrieved (None)
Traceback (most recent call last):
  File "/usr/src/homeassistant/homeassistant/helpers/update_coordinator.py", line 267, in _handle_refresh_interval
    await self._async_refresh(log_failures=True, scheduled=True)
  File "/usr/src/homeassistant/homeassistant/helpers/update_coordinator.py", line 478, in _async_refresh
    self.async_update_listeners()
    ~~~~~~~~~~~~~~~~~~~~~~~~~~~^^
  File "/usr/src/homeassistant/homeassistant/helpers/update_coordinator.py", line 177, in async_update_listeners
    update_callback()
    ~~~~~~~~~~~~~~~^^
  File "/usr/src/homeassistant/homeassistant/components/tesla_fleet/entity.py", line 83, in _handle_coordinator_update
    self._async_update_attrs()
    ~~~~~~~~~~~~~~~~~~~~~~~~^^
  File "/usr/src/homeassistant/homeassistant/components/tesla_fleet/select.py", line 188, in _async_update_attrs
    self._attr_current_option = self._attr_options[value]
                                ~~~~~~~~~~~~~~~~~~^^^^^^^
IndexError: list index out of range
2025-01-12 14:33:25.080 ERROR (MainThread) [homeassistant.components.websocket_api.http.connection] [140124433162752] Supervisor from 172.30.32.2 (HomeAssistantSupervisor/2024.12.3 aiohttp/3.11.11 Python/3.12): Unexpected error inside websocket API
Traceback (most recent call last):
  File "/usr/src/homeassistant/homeassistant/components/websocket_api/http.py", line 343, in async_handle
    await self._async_websocket_command_phase(connection)
  File "/usr/src/homeassistant/homeassistant/components/websocket_api/http.py", line 463, in _async_websocket_command_phase
    msg = await wsock.receive()
          ^^^^^^^^^^^^^^^^^^^^^
  File "/usr/local/lib/python3.13/site-packages/aiohttp/web_ws.py", line 575, in receive
    await self.pong(msg.data)
  File "/usr/local/lib/python3.13/site-packages/aiohttp/web_ws.py", line 393, in pong
    await self._writer.send_frame(message, WSMsgType.PONG)
  File "/usr/local/lib/python3.13/site-packages/aiohttp/_websocket/writer.py", line 125, in send_frame
    raise ClientConnectionResetError("Cannot write to closing transport")
aiohttp.client_exceptions.ClientConnectionResetError: Cannot write to closing transport
2025-01-12 14:41:04.253 ERROR (MainThread) [homeassistant.components.template.template_entity] TemplateError('ValueError: Template error: float got invalid input 'unavailable' when rendering template '{{ ((states('sensor.illuminance_front_entry') | float + states('sensor.illuminance_dining_room') | float) / 2) | round(1) }}' but no default was specified') while processing template 'Template<template=({{ ((states('sensor.illuminance_front_entry') | float + states('sensor.illuminance_dining_room') | float) / 2) | round(1) }}) renders=312>' for attribute '_attr_native_value' in entity 'sensor.overall_living_area_illuminance'
